Workbook

Sheet MAIN
A1: Stress_Scenarios | B1: Short_des | C1: code | D1: Long_des | E1: Unnamed: 6 | F1: Factors1 | G1: TITLE | H1: Factors2 | I1: FACTOR_TAG | J1: Check | K1: Mapping 3 livello | L1: Factor_type | M1: Mapping 2 livello | N1: Mapping 1 Livello | O1: Shock_Value
A2: 1995_MCADJ | B2: Mid-cycle adjustment Mar 1995-Dec 1995 | C2: 2302 | D2: Scenario to capture the mid-cycle adjustment of the 1995, based on historical factor returns during the period Mar1995 to Dec1995. | E2: Tsy 3M USD_3m - Yield: -76.00bps, | F2: Tsy 3M | G2: =+VLOOKUP(F2,[1]Explore!$B:$I,8,0) -> Govt USD | H2: USD_3m | I2: =+VLOOKUP(H2,[1]Explore!$A:$I,9,0) -> Govt USD | J2: =IF(AND(ISNA(G2),ISNA(I2)),"BOTH #N/A","OK") -> OK | K2: =IFERROR(I2, IFERROR(G2, L2)) -> Govt USD | L2: Yield | M2: =_xlfn.IFNA(VLOOKUP(K2,'Mapping DEF'!A:C,2,0),"") -> Curve (Local) | N2: =+_xlfn.IFNA(VLOOKUP(M2,'Mapping DEF'!B:C,2,FALSE),"") -> Term Structure | O2: -76.00bps
A3: 1995_MCADJ | B3: Mid-cycle adjustment Mar 1995-Dec 1995 | C3: 2302 | D3: Scenario to capture the mid-cycle adjustment of the 1995, based on historical factor returns during the period Mar1995 to Dec1995. | E3: Tsy 1Y USD_1yr - Yield: -129.00bps, | F3: Tsy 1Y | G3: =+VLOOKUP(F3,[1]Explore!$B:$I,8,0) -> Govt USD | H3: USD_1yr | I3: =+VLOOKUP(H3,[1]Explore!$A:$I,9,0) -> Govt USD | J3: =IF(AND(ISNA(G3),ISNA(I3)),"BOTH #N/A","OK") -> OK | K3: =IFERROR(I3, IFERROR(G3, L3)) -> Govt USD | L3: Yield | M3: =_xlfn.IFNA(VLOOKUP(K3,'Mapping DEF'!A:C,2,0),"") -> Curve (Local) | N3: =+_xlfn.IFNA(VLOOKUP(M3,'Mapping DEF'!B:C,2,FALSE),"") -> Term Structure | O3: -129.00bps
A4: 1995_MCADJ | B4: Mid-cycle adjustment Mar 1995-Dec 1995 | C4: 2302 | D4: Scenario to capture the mid-cycle adjustment of the 1995, based on historical factor returns during the period Mar1995 to Dec1995. | E4: Tsy 2Y USD_2yr - Yield: -164.00bps, | F4: Tsy 2Y | G4: =+VLOOKUP(F4,[1]Explore!$B:$I,8,0) -> Govt USD | H4: USD_2yr | I4: =+VLOOKUP(H4,[1]Explore!$A:$I,9,0) -> Govt USD | J4: =IF(AND(ISNA(G4),ISNA(I4)),"BOTH #N/A","OK") -> OK | K4: =IFERROR(I4, IFERROR(G4, L4)) -> Govt USD | L4: Yield | M4: =_xlfn.IFNA(VLOOKUP(K4,'Mapping DEF'!A:C,2,0),"") -> Curve (Local) | N4: =+_xlfn.IFNA(VLOOKUP(M4,'Mapping DEF'!B:C,2,FALSE),"") -> Term Structure | O4: -164.00bps
A5: 1995_MCADJ | B5: Mid-cycle adjustment Mar 1995-Dec 1995 | C5: 2302 | D5: Scenario to capture the mid-cycle adjustment of the 1995, based on historical factor returns during the period Mar1995 to Dec1995. | E5: Tsy 5Y USD_5yr - Yield: -169.00bps, | F5: Tsy 5Y | G5: =+VLOOKUP(F5,[1]Explore!$B:$I,8,0) -> Govt USD | H5: USD_5yr | I5: =+VLOOKUP(H5,[1]Explore!$A:$I,9,0) -> Govt USD | J5: =IF(AND(ISNA(G5),ISNA(I5)),"BOTH #N/A","OK") -> OK | K5: =IFERROR(I5, IFERROR(G5, L5)) -> Govt USD | L5: Yield | M5: =_xlfn.IFNA(VLOOKUP(K5,'Mapping DEF'!A:C,2,0),"") -> Curve (Local) | N5: =+_xlfn.IFNA(VLOOKUP(M5,'Mapping DEF'!B:C,2,FALSE),"") -> Term Structure | O5: -169.00bps
A6: 1995_MCADJ | B6: Mid-cycle adjustment Mar 1995-Dec 1995 | C6: 2302 | D6: Scenario to capture the mid-cycle adjustment of the 1995, based on historical factor returns during the period Mar1995 to Dec1995. | E6: Tsy 10Y USD_10yr - Yield: -162.00bps, | F6: Tsy 10Y | G6: =+VLOOKUP(F6,[1]Explore!$B:$I,8,0) -> Govt USD | H6: USD_10yr | I6: =+VLOOKUP(H6,[1]Explore!$A:$I,9,0) -> Govt USD | J6: =IF(AND(ISNA(G6),ISNA(I6)),"BOTH #N/A","OK") -> OK | K6: =IFERROR(I6, IFERROR(G6, L6)) -> Govt USD | L6: Yield | M6: =_xlfn.IFNA(VLOOKUP(K6,'Mapping DEF'!A:C,2,0),"") -> Curve (Local) | N6: =+_xlfn.IFNA(VLOOKUP(M6,'Mapping DEF'!B:C,2,FALSE),"") -> Term Structure | O6: -162.00bps
A7: 1995_MCADJ | B7: Mid-cycle adjustment Mar 1995-Dec 1995 | C7: 2302 | D7: Scenario to capture the mid-cycle adjustment of the 1995, based on historical factor returns during the period Mar1995 to Dec1995. | E7: Tsy 30Y USD_30yr - Yield: -139.00bps, | F7: Tsy 30Y | G7: =+VLOOKUP(F7,[1]Explore!$B:$I,8,0) -> Govt USD | H7: USD_30yr | I7: =+VLOOKUP(H7,[1]Explore!$A:$I,9,0) -> Govt USD | J7: =IF(AND(ISNA(G7),ISNA(I7)),"BOTH #N/A","OK") -> OK | K7: =IFERROR(I7, IFERROR(G7, L7)) -> Govt USD | L7: Yield | M7: =_xlfn.IFNA(VLOOKUP(K7,'Mapping DEF'!A:C,2,0),"") -> Curve (Local) | N7: =+_xlfn.IFNA(VLOOKUP(M7,'Mapping DEF'!B:C,2,FALSE),"") -> Term Structure | O7: -139.00bps
A8: 1995_MCADJ | B8: Mid-cycle adjustment Mar 1995-Dec 1995 | C8: 2302 | D8: Scenario to capture the mid-cycle adjustment of the 1995, based on historical factor returns during the period Mar1995 to Dec1995. | E8: SP500 Consum Discr S5COND - Index Level: 17.00pct, | F8: SP500 Consum Discr | G8: =+VLOOKUP(F8,[1]Explore!$B:$I,8,0) -> Equity Implied Volatility | H8: S5COND | I8: =+VLOOKUP(H8,[1]Explore!$A:$I,9,0) -> Equity Implied Volatility | J8: =IF(AND(ISNA(G8),ISNA(I8)),"BOTH #N/A","OK") -> OK | K8: =IFERROR(I8, IFERROR(G8, L8)) -> Equity Implied Volatility | L8: Index Level | M8: =_xlfn.IFNA(VLOOKUP(K8,'Mapping DEF'!A:C,2,0),"") -> Equity Derivatives | N8: =+_xlfn.IFNA(VLOOKUP(M8,'Mapping DEF'!B:C,2,FALSE),"") -> Equity | O8: 17.00pct
A9: 1995_MCADJ | B9: Mid-cycle adjustment Mar 1995-Dec 1995 | C9: 2302 | D9: Scenario to capture the mid-cycle adjustment of the 1995, based on historical factor returns during the period Mar1995 to Dec1995. | E9: SP500 Consum Stapl S5CONS - Index Level: 24.00pct, | F9: SP500 Consum Stapl | G9: =+VLOOKUP(F9,[1]Explore!$B:$I,8,0) -> Equity Implied Volatility | H9: S5CONS | I9: =+VLOOKUP(H9,[1]Explore!$A:$I,9,0) -> Equity Implied Volatility | J9: =IF(AND(ISNA(G9),ISNA(I9)),"BOTH #N/A","OK") -> OK | K9: =IFERROR(I9, IFERROR(G9, L9)) -> Equity Implied Volatility | L9: Index Level | M9: =_xlfn.IFNA(VLOOKUP(K9,'Mapping DEF'!A:C,2,0),"") -> Equity Derivatives | N9: =+_xlfn.IFNA(VLOOKUP(M9,'Mapping DEF'!B:C,2,FALSE),"") -> Equity | O9: 24.00pct
A10: 1995_MCADJ | B10: Mid-cycle adjustment Mar 1995-Dec 1995 | C10: 2302 | D10: Scenario to capture the mid-cycle adjustment of the 1995, based on historical factor returns during the period Mar1995 to Dec1995. | E10: S&P 500 Energy S5ENRS - Index Level: 29.00pct, | F10: S&P 500 Energy | G10: =+VLOOKUP(F10,[1]Explore!$B:$I,8,0) -> Equity Implied Volatility | H10: S5ENRS | I10: =+VLOOKUP(H10,[1]Explore!$A:$I,9,0) -> Equity Implied Volatility | J10: =IF(AND(ISNA(G10),ISNA(I10)),"BOTH #N/A","OK") -> OK | K10: =IFERROR(I10, IFERROR(G10, L10)) -> Equity Implied Volatility | L10: Index Level | M10: =_xlfn.IFNA(VLOOKUP(K10,'Mapping DEF'!A:C,2,0),"") -> Equity Derivatives | N10: =+_xlfn.IFNA(VLOOKUP(M10,'Mapping DEF'!B:C,2,FALSE),"") -> Equity | O10: 29.00pct
A11: 1995_MCADJ | B11: Mid-cycle adjustment Mar 1995-Dec 1995 | C11: 2302 | D11: Scenario to capture the mid-cycle adjustment of the 1995, based on historical factor returns during the period Mar1995 to Dec1995. | E11: S&P 500 Financials S5FINL - Index Level: 38.00pct, | F11: S&P 500 Financials | G11: =+VLOOKUP(F11,[1]Explore!$B:$I,8,0) -> Equity Implied Volatility | H11: S5FINL | I11: =+VLOOKUP(H11,[1]Explore!$A:$I,9,0) -> Equity Implied Volatility | J11: =IF(AND(ISNA(G11),ISNA(I11)),"BOTH #N/A","OK") -> OK | K11: =IFERROR(I11, IFERROR(G11, L11)) -> Equity Implied Volatility | L11: Index Level | M11: =_xlfn.IFNA(VLOOKUP(K11,'Mapping DEF'!A:C,2,0),"") -> Equity Derivatives | N11: =+_xlfn.IFNA(VLOOKUP(M11,'Mapping DEF'!B:C,2,FALSE),"") -> Equity | O11: 38.00pct
A12: 1995_MCADJ | B12: Mid-cycle adjustment Mar 1995-Dec 1995 | C12: 2302 | D12: Scenario to capture the mid-cycle adjustment of the 1995, based on historical factor returns during the period Mar1995 to Dec1995. | E12: S&P 500 Health Care S5HLTH - Index Level: 33.00pct, | F12: S&P 500 Health Care | G12: =+VLOOKUP(F12,[1]Explore!$B:$I,8,0) -> Equity Implied Volatility | H12: S5HLTH | I12: =+VLOOKUP(H12,[1]Explore!$A:$I,9,0) -> Equity Implied Volatility | J12: =IF(AND(ISNA(G12),ISNA(I12)),"BOTH #N/A","OK") -> OK | K12: =IFERROR(I12, IFERROR(G12, L12)) -> Equity Implied Volatility | L12: Index Level | M12: =_xlfn.IFNA(VLOOKUP(K12,'Mapping DEF'!A:C,2,0),"") -> Equity Derivatives | N12: =+_xlfn.IFNA(VLOOKUP(M12,'Mapping DEF'!B:C,2,FALSE),"") -> Equity | O12: 33.00pct
A13: 1995_MCADJ | B13: Mid-cycle adjustment Mar 1995-Dec 1995 | C13: 2302 | D13: Scenario to capture the mid-cycle adjustment of the 1995, based on historical factor returns during the period Mar1995 to Dec1995. | E13: S&P 500 Industrials S5INDU - Index Level: 26.00pct, | F13: S&P 500 Industrials | G13: =+VLOOKUP(F13,[1]Explore!$B:$I,8,0) -> Equity Implied Volatility | H13: S5INDU | I13: =+VLOOKUP(H13,[1]Explore!$A:$I,9,0) -> Equity Implied Volatility | J13: =IF(AND(ISNA(G13),ISNA(I13)),"BOTH #N/A","OK") -> OK | K13: =IFERROR(I13, IFERROR(G13, L13)) -> Equity Implied Volatility | L13: Index Level | M13: =_xlfn.IFNA(VLOOKUP(K13,'Mapping DEF'!A:C,2,0),"") -> Equity Derivatives | N13: =+_xlfn.IFNA(VLOOKUP(M13,'Mapping DEF'!B:C,2,FALSE),"") -> Equity | O13: 26.00pct
... A22: AICHEV | B22: U.S. Global AI Diffusion: Evasion & Diversion (06/2025) | C22: 2109 | D22: Increased technology flow to allies under the replacement framework enables China and other adversaries to successfully acquire advanced US AI chips through evasion. | E22: Electrical Equipment - Electrical Equipment [FMI_CHNA_INDELECEQ-FMI_NAMR_INDELECEQ] - Industry Return: 10.00pct, | F22: Electrical Equipment | G22: =+VLOOKUP(F22,[1]Explore!$B:$I,8,0) -> Industrials | H22: Equipment | I22: =+VLOOKUP(H22,[1]Explore!$A:$I,9,0) -> #N/A | J22: =IF(AND(ISNA(G22),ISNA(I22)),"BOTH #N/A","OK") -> OK | K22: =IFERROR(I22, IFERROR(G22, L22)) -> Industrials | L22: Industry Return | M22: =_xlfn.IFNA(VLOOKUP(K22,'Mapping DEF'!A:C,2,0),"") -> Industry Allocation | N22: =+_xlfn.IFNA(VLOOKUP(M22,'Mapping DEF'!B:C,2,FALSE),"") -> Equity | O22: 10.00pct
A23: AICHEV | B23: U.S. Global AI Diffusion: Evasion & Diversion (06/2025) | C23: 2109 | D23: Increased technology flow to allies under the replacement framework enables China and other adversaries to successfully acquire advanced US AI chips through evasion. | E23: Semiconductors - Semiconductors & Equipment [FMI_CHNA_ITCSEMICON-FMI_NAMR_ITCSEMICEQ] - Industry Return: 30.00pct, | F23: Semiconductors & Equipment | G23: =+VLOOKUP(F23,[1]Explore!$B:$I,8,0) -> Information Technology | I23: =+VLOOKUP(H23,[1]Explore!$A:$I,9,0) -> #N/A | J23: =IF(AND(ISNA(G23),ISNA(I23)),"BOTH #N/A","OK") -> OK | K23: =IFERROR(I23, IFERROR(G23, L23)) -> Information Technology | L23: Industry Return | M23: =_xlfn.IFNA(VLOOKUP(K23,'Mapping DEF'!A:C,2,0),"") -> Industry Allocation | N23: =+_xlfn.IFNA(VLOOKUP(M23,'Mapping DEF'!B:C,2,FALSE),"") -> Equity | O23: 30.00pct
A24: AICHEV | B24: U.S. Global AI Diffusion: Evasion & Diversion (06/2025) | C24: 2109 | D24: Increased technology flow to allies under the replacement framework enables China and other adversaries to successfully acquire advanced US AI chips through evasion. | E24: US HY Other Technology - US HY Market [USD_HY_TECHOTHR_SF-USD_HY_MARKET_SF] - Spread Yield: 50.00bps | F24: US HY Other Technology | G24: =+VLOOKUP(F24,[1]Explore!$B:$I,8,0) -> Corporate HY USD - Industry | H24: Technology | I24: =+VLOOKUP(H24,[1]Explore!$A:$I,9,0) -> #N/A | J24: =IF(AND(ISNA(G24),ISNA(I24)),"BOTH #N/A","OK") -> OK | K24: =IFERROR(I24, IFERROR(G24, L24)) -> Corporate HY USD - Industry | L24: Spread Yield | M24: =_xlfn.IFNA(VLOOKUP(K24,'Mapping DEF'!A:C,2,0),"") -> Spread | N24: =+_xlfn.IFNA(VLOOKUP(M24,'Mapping DEF'!B:C,2,FALSE),"") -> Spread | O24: 50.00bps
A25: AICHRET | B25: U.S. Global AI Diffusion: China Retaliation (06/2025) | C25: 2108 | D25: In response to the US export restrictions under the replacement framework, China?s retaliatory response involves imposing rare earth export limits to hinder U.S. chip manufacturing. | E25: GSCI PRECIOUS METALS GSPMSPOT - Price Level: 15.00pct, | F25: GSCI PRECIOUS METALS | G25: =+VLOOKUP(F25,[1]Explore!$B:$I,8,0) -> Alternative - Commodity | H25: GSPMSPOT | I25: =+VLOOKUP(H25,[1]Explore!$A:$I,9,0) -> Alternative - Commodity | J25: =IF(AND(ISNA(G25),ISNA(I25)),"BOTH #N/A","OK") -> OK | K25: =IFERROR(I25, IFERROR(G25, L25)) -> Alternative - Commodity | L25: Price Level | M25: =_xlfn.IFNA(VLOOKUP(K25,'Mapping DEF'!A:C,2,0),"") -> Alternative | N25: =+_xlfn.IFNA(VLOOKUP(M25,'Mapping DEF'!B:C,2,FALSE),"") -> Other | O25: 15.00pct
A26: AICHRET | B26: U.S. Global AI Diffusion: China Retaliation (06/2025) | C26: 2108 | D26: In response to the US export restrictions under the replacement framework, China?s retaliatory response involves imposing rare earth export limits to hinder U.S. chip manufacturing. | E26: Alum Div Metals & Mining FMI_NAMR_MATALUDIV - Industry Return: 10.00pct, | F26: Alum Div Metals & Mining | G26: =+VLOOKUP(F26,[1]Explore!$B:$I,8,0) -> #N/A | H26: FMI_NAMR_MATALUDIV | I26: =+VLOOKUP(H26,[1]Explore!$A:$I,9,0) -> #N/A | J26: =IF(AND(ISNA(G26),ISNA(I26)),"BOTH #N/A","OK") -> BOTH #N/A | K26: =IFERROR(I26, IFERROR(G26, L26)) -> Materials | L26: Materials | M26: =_xlfn.IFNA(VLOOKUP(K26,'Mapping DEF'!A:C,2,0),"") -> Industry Allocation | N26: =+_xlfn.IFNA(VLOOKUP(M26,'Mapping DEF'!B:C,2,FALSE),"") -> Equity | O26: 10.00pct
A27: AICHRET | B27: U.S. Global AI Diffusion: China Retaliation (06/2025) | C27: 2108 | D27: In response to the US export restrictions under the replacement framework, China?s retaliatory response involves imposing rare earth export limits to hinder U.S. chip manufacturing. | E27: Electrical Equipment FMI_NAMR_INDELECEQ - Industry Return: -15.00pct, | F27: Electrical Equipment | G27: =+VLOOKUP(F27,[1]Explore!$B:$I,8,0) -> Industrials | H27: FMI_NAMR_INDELECEQ | I27: =+VLOOKUP(H27,[1]Explore!$A:$I,9,0) -> #N/A | J27: =IF(AND(ISNA(G27),ISNA(I27)),"BOTH #N/A","OK") -> OK | K27: =IFERROR(I27, IFERROR(G27, L27)) -> Industrials | L27: Industry Return | M27: =_xlfn.IFNA(VLOOKUP(K27,'Mapping DEF'!A:C,2,0),"") -> Industry Allocation | N27: =+_xlfn.IFNA(VLOOKUP(M27,'Mapping DEF'!B:C,2,FALSE),"") -> Equity | O27: -15.00pct
A28: AICHRET | B28: U.S. Global AI Diffusion: China Retaliation (06/2025) | C28: 2108 | D28: In response to the US export restrictions under the replacement framework, China?s retaliatory response involves imposing rare earth export limits to hinder U.S. chip manufacturing. | E28: Software & Internet Services FMI_CHNA_ITCSOFTNET - Industry Return: 10.00pct, | F28: Software & Internet Services | G28: =+VLOOKUP(F28,[1]Explore!$B:$I,8,0) -> #N/A | H28: FMI_CHNA_ITCSOFTNET | I28: =+VLOOKUP(H28,[1]Explore!$A:$I,9,0) -> #N/A | J28: =IF(AND(ISNA(G28),ISNA(I28)),"BOTH #N/A","OK") -> BOTH #N/A | K28: =IFERROR(I28, IFERROR(G28, L28)) -> Information Technology | L28: Information Technology | M28: =_xlfn.IFNA(VLOOKUP(K28,'Mapping DEF'!A:C,2,0),"") -> Industry Allocation | N28: =+_xlfn.IFNA(VLOOKUP(M28,'Mapping DEF'!B:C,2,FALSE),"") -> Equity | O28: 10.00pct
A29: AICHRET | B29: U.S. Global AI Diffusion: China Retaliation (06/2025) | C29: 2108 | D29: In response to the US export restrictions under the replacement framework, China?s retaliatory response involves imposing rare earth export limits to hinder U.S. chip manufacturing. | E29: US HY Tech Hardware - US HY Market [USD_HY_HARDWARE_SF-USD_HY_MARKET_SF] - Spread Yield: 100.00bps | F29: US HY Tech Hardware | G29: =+VLOOKUP(F29,[1]Explore!$B:$I,8,0) -> Corporate HY USD - Industry | H29: Hardware | I29: =+VLOOKUP(H29,[1]Explore!$A:$I,9,0) -> #N/A | J29: =IF(AND(ISNA(G29),ISNA(I29)),"BOTH #N/A","OK") -> OK | K29: =IFERROR(I29, IFERROR(G29, L29)) -> Corporate HY USD - Industry | L29: Spread Yield | M29: =_xlfn.IFNA(VLOOKUP(K29,'Mapping DEF'!A:C,2,0),"") -> Spread | N29: =+_xlfn.IFNA(VLOOKUP(M29,'Mapping DEF'!B:C,2,FALSE),"") -> Spread | O29: 100.00bps
A30: AITWNBL | B30: U.S. Global AI Diffusion: China Blockade on Taiwan (06/2025) | C30: 2107 | D30: As an ultimatum to the AI war, China imposes a blockade of Taiwan, forcing it to stop chip exports to the US, causing the largest major supply chain disruption the US semiconductor industry has ever experienced. | E30: Tsy 5Y USD_5yr - Yield: 100.00bps, | F30: Tsy 5Y | G30: =+VLOOKUP(F30,[1]Explore!$B:$I,8,0) -> Govt USD | H30: USD_5yr | I30: =+VLOOKUP(H30,[1]Explore!$A:$I,9,0) -> Govt USD | J30: =IF(AND(ISNA(G30),ISNA(I30)),"BOTH #N/A","OK") -> OK | K30: =IFERROR(I30, IFERROR(G30, L30)) -> Govt USD | L30: Yield | M30: =_xlfn.IFNA(VLOOKUP(K30,'Mapping DEF'!A:C,2,0),"") -> Curve (Local) | N30: =+_xlfn.IFNA(VLOOKUP(M30,'Mapping DEF'!B:C,2,FALSE),"") -> Term Structure | O30: 100.00bps
A31: AITWNBL | B31: U.S. Global AI Diffusion: China Blockade on Taiwan (06/2025) | C31: 2107 | D31: As an ultimatum to the AI war, China imposes a blockade of Taiwan, forcing it to stop chip exports to the US, causing the largest major supply chain disruption the US semiconductor industry has ever experienced. | E31: GSCI PRECIOUS METALS GSPMSPOT - Price Level: -10.00pct, | F31: GSCI PRECIOUS METALS | G31: =+VLOOKUP(F31,[1]Explore!$B:$I,8,0) -> Alternative - Commodity | H31: GSPMSPOT | I31: =+VLOOKUP(H31,[1]Explore!$A:$I,9,0) -> Alternative - Commodity | J31: =IF(AND(ISNA(G31),ISNA(I31)),"BOTH #N/A","OK") -> OK | K31: =IFERROR(I31, IFERROR(G31, L31)) -> Alternative - Commodity | L31: Price Level | M31: =_xlfn.IFNA(VLOOKUP(K31,'Mapping DEF'!A:C,2,0),"") -> Alternative | N31: =+_xlfn.IFNA(VLOOKUP(M31,'Mapping DEF'!B:C,2,FALSE),"") -> Other | O31: -10.00pct
A32: AITWNBL | B32: U.S. Global AI Diffusion: China Blockade on Taiwan (06/2025) | C32: 2107 | D32: As an ultimatum to the AI war, China imposes a blockade of Taiwan, forcing it to stop chip exports to the US, causing the largest major supply chain disruption the US semiconductor industry has ever experienced. | E32: CNY/USD CNY_FX_USD - FX: 5.00pct, | F32: CNYUSD | G32: =+VLOOKUP(F32,[1]Explore!$B:$I,8,0) -> #N/A | H32: CNY_FX_USD | I32: =+VLOOKUP(H32,[1]Explore!$A:$I,9,0) -> Emerging Currency | J32: =IF(AND(ISNA(G32),ISNA(I32)),"BOTH #N/A","OK") -> OK | K32: =IFERROR(I32, IFERROR(G32, L32)) -> Emerging Currency | L32: FX | M32: =_xlfn.IFNA(VLOOKUP(K32,'Mapping DEF'!A:C,2,0),"") -> FX | N32: =+_xlfn.IFNA(VLOOKUP(M32,'Mapping DEF'!B:C,2,FALSE),"") -> FX | O32: 5.00pct
A33: AITWNBL | B33: U.S. Global AI Diffusion: China Blockade on Taiwan (06/2025) | C33: 2107 | D33: As an ultimatum to the AI war, China imposes a blockade of Taiwan, forcing it to stop chip exports to the US, causing the largest major supply chain disruption the US semiconductor industry has ever experienced. | E33: Taiwan TWSE TWSE - Index Level: -30.00pct, | F33: Taiwan TWSE | G33: =+VLOOKUP(F33,[1]Explore!$B:$I,8,0) -> Equity Implied Volatility | H33: TWSE | I33: =+VLOOKUP(H33,[1]Explore!$A:$I,9,0) -> Equity Implied Volatility | J33: =IF(AND(ISNA(G33),ISNA(I33)),"BOTH #N/A","OK") -> OK | K33: =IFERROR(I33, IFERROR(G33, L33)) -> Equity Implied Volatility | L33: Index Level | M33: =_xlfn.IFNA(VLOOKUP(K33,'Mapping DEF'!A:C,2,0),"") -> Equity Derivatives | N33: =+_xlfn.IFNA(VLOOKUP(M33,'Mapping DEF'!B:C,2,FALSE),"") -> Equity | O33: -30.00pct
A34: AITWNBL | B34: U.S. Global AI Diffusion: China Blockade on Taiwan (06/2025) | C34: 2107 | D34: As an ultimatum to the AI war, China imposes a blockade of Taiwan, forcing it to stop chip exports to the US, causing the largest major supply chain disruption the US semiconductor industry has ever experienced. | E34: Aerospace & Defense FMI_NAMR_INDAIRDEF - Industry Return: 25.00pct, | F34: Aerospace & Defense | G34: =+VLOOKUP(F34,[1]Explore!$B:$I,8,0) -> Industrials | H34: FMI_NAMR_INDAIRDEF | I34: =+VLOOKUP(H34,[1]Explore!$A:$I,9,0) -> #N/A | J34: =IF(AND(ISNA(G34),ISNA(I34)),"BOTH #N/A","OK") -> OK | K34: =IFERROR(I34, IFERROR(G34, L34)) -> Industrials | L34: Industry Return | M34: =_xlfn.IFNA(VLOOKUP(K34,'Mapping DEF'!A:C,2,0),"") -> Industry Allocation | N34: =+_xlfn.IFNA(VLOOKUP(M34,'Mapping DEF'!B:C,2,FALSE),"") -> Equity | O34: 25.00pct
A35: AITWNBL | B35: U.S. Global AI Diffusion: China Blockade on Taiwan (06/2025) | C35: 2107 | D35: As an ultimatum to the AI war, China imposes a blockade of Taiwan, forcing it to stop chip exports to the US, causing the largest major supply chain disruption the US semiconductor industry has ever experienced. | E35: Semiconductors & Equipment FMI_NAMR_ITCSEMICEQ - Industry Return: -35.00pct, | F35: Semiconductors & Equipment | G35: =+VLOOKUP(F35,[1]Explore!$B:$I,8,0) -> Information Technology | H35: FMI_NAMR_ITCSEMICEQ | I35: =+VLOOKUP(H35,[1]Explore!$A:$I,9,0) -> #N/A | J35: =IF(AND(ISNA(G35),ISNA(I35)),"BOTH #N/A","OK") -> OK | K35: =IFERROR(I35, IFERROR(G35, L35)) -> Information Technology | L35: Industry Return | M35: =_xlfn.IFNA(VLOOKUP(K35,'Mapping DEF'!A:C,2,0),"") -> Industry Allocation | N35: =+_xlfn.IFNA(VLOOKUP(M35,'Mapping DEF'!B:C,2,FALSE),"") -> Equity | O35: -35.00pct
... A81: BTAX_COMP | B81: US Corporate Tax Reform - Compromise Plan (07/2021) | C81: 2460 | D81: A dialed down tax reform package passes, but US EU trade tensions rise over digital services taxes. | E81: MSCI EUROPE(EUR) - MSCI World Net TR [MXEU-MSCIWLDNET] - Index Level: -2.00pct | F81: MSCI EUROPE(EUR) | G81: =+VLOOKUP(F81,[1]Explore!$B:$I,8,0) -> Equity Implied Volatility | H81: EUROPEEUR | I81: =+VLOOKUP(H81,[1]Explore!$A:$I,9,0) -> #N/A | J81: =IF(AND(ISNA(G81),ISNA(I81)),"BOTH #N/A","OK") -> OK | K81: =IFERROR(I81, IFERROR(G81, L81)) -> Equity Implied Volatility | L81: Index Level | M81: =_xlfn.IFNA(VLOOKUP(K81,'Mapping DEF'!A:C,2,0),"") -> Equity Derivatives | N81: =+_xlfn.IFNA(VLOOKUP(M81,'Mapping DEF'!B:C,2,FALSE),"") -> Equity | O81: -2.00pct
A82: C07_ABS | B82: Credit '07 - Absolute, Jul 01, 2007 - Jul 01, 2008 | C82: 2308 | D82: Credit & liquidity crisis stemming from a severe slowdown in the housing market causing significant widening of credit spreads and increased implied volatility. Shocks for DxS Factors are spreads. | E82: - | G82: =+VLOOKUP(F82,[1]Explore!$B:$I,8,0) -> #N/A | H82: - | I82: =+VLOOKUP(H82,[1]Explore!$A:$I,9,0) -> #N/A | J82: =IF(AND(ISNA(G82),ISNA(I82)),"BOTH #N/A","OK") -> BOTH #N/A | K82: =IFERROR(I82, IFERROR(G82, L82)) -> - | L82: - | M82: =_xlfn.IFNA(VLOOKUP(K82,'Mapping DEF'!A:C,2,0),"") | N82: =+_xlfn.IFNA(VLOOKUP(M82,'Mapping DEF'!B:C,2,FALSE),"")
A83: C08_REL | B83: Crash '08 - Relative, Sep 12 - Nov 03, 2008 | C83: 2309 | D83: Credit & liquidity crisis and equity market crash set off by Lehman Brothers bankruptcy. Significant credit spreads widening caused by massive deleveraging. Shocks for DxS Factors are percentages of spread. | E83: - | G83: =+VLOOKUP(F83,[1]Explore!$B:$I,8,0) -> #N/A | H83: - | I83: =+VLOOKUP(H83,[1]Explore!$A:$I,9,0) -> #N/A | J83: =IF(AND(ISNA(G83),ISNA(I83)),"BOTH #N/A","OK") -> BOTH #N/A | K83: =IFERROR(I83, IFERROR(G83, L83)) -> - | L83: - | M83: =_xlfn.IFNA(VLOOKUP(K83,'Mapping DEF'!A:C,2,0),"") | N83: =+_xlfn.IFNA(VLOOKUP(M83,'Mapping DEF'!B:C,2,FALSE),"")
A84: CB_OVER | B84: Fed Policy at Growth Inflection-Economy Overheats(08/2021) | C84: 2461 | D84: The US economy recovers sharply following a successful vaccine rollout, leading to elevated risk asset valuations and unexpectedly high inflation. Faced with apparent economic overheating, the Fed hastens its tapering of asset purchases and pulls rate hike expectations forward to early 2022. | E84: Tsy 2Y USD_2yr - Yield: 20.00bps, | F84: Tsy 2Y | G84: =+VLOOKUP(F84,[1]Explore!$B:$I,8,0) -> Govt USD | H84: USD_2yr | I84: =+VLOOKUP(H84,[1]Explore!$A:$I,9,0) -> Govt USD | J84: =IF(AND(ISNA(G84),ISNA(I84)),"BOTH #N/A","OK") -> OK | K84: =IFERROR(I84, IFERROR(G84, L84)) -> Govt USD | L84: Yield | M84: =_xlfn.IFNA(VLOOKUP(K84,'Mapping DEF'!A:C,2,0),"") -> Curve (Local) | N84: =+_xlfn.IFNA(VLOOKUP(M84,'Mapping DEF'!B:C,2,FALSE),"") -> Term Structure | O84: 20.00bps
A85: CB_OVER | B85: Fed Policy at Growth Inflection-Economy Overheats(08/2021) | C85: 2461 | D85: The US economy recovers sharply following a successful vaccine rollout, leading to elevated risk asset valuations and unexpectedly high inflation. Faced with apparent economic overheating, the Fed hastens its tapering of asset purchases and pulls rate hike expectations forward to early 2022. | E85: Tsy 10Y USD_10yr - Yield: 45.00bps, | F85: Tsy 10Y | G85: =+VLOOKUP(F85,[1]Explore!$B:$I,8,0) -> Govt USD | H85: USD_10yr | I85: =+VLOOKUP(H85,[1]Explore!$A:$I,9,0) -> Govt USD | J85: =IF(AND(ISNA(G85),ISNA(I85)),"BOTH #N/A","OK") -> OK | K85: =IFERROR(I85, IFERROR(G85, L85)) -> Govt USD | L85: Yield | M85: =_xlfn.IFNA(VLOOKUP(K85,'Mapping DEF'!A:C,2,0),"") -> Curve (Local) | N85: =+_xlfn.IFNA(VLOOKUP(M85,'Mapping DEF'!B:C,2,FALSE),"") -> Term Structure | O85: 45.00bps
A86: CB_OVER | B86: Fed Policy at Growth Inflection-Economy Overheats(08/2021) | C86: 2461 | D86: The US economy recovers sharply following a successful vaccine rollout, leading to elevated risk asset valuations and unexpectedly high inflation. Faced with apparent economic overheating, the Fed hastens its tapering of asset purchases and pulls rate hike expectations forward to early 2022. | E86: USD INF 10Y USD_INF_10yr - Yield: -50.00bps, | F86: USD INF 10Y | G86: =+VLOOKUP(F86,[1]Explore!$B:$I,8,0) -> USD Inflation | H86: USD_INF_10yr | I86: =+VLOOKUP(H86,[1]Explore!$A:$I,9,0) -> USD Inflation | J86: =IF(AND(ISNA(G86),ISNA(I86)),"BOTH #N/A","OK") -> OK | K86: =IFERROR(I86, IFERROR(G86, L86)) -> USD Inflation | L86: Yield | M86: =_xlfn.IFNA(VLOOKUP(K86,'Mapping DEF'!A:C,2,0),"") -> Inflation | N86: =+_xlfn.IFNA(VLOOKUP(M86,'Mapping DEF'!B:C,2,FALSE),"") -> Other | O86: -50.00bps
A87: CB_OVER | B87: Fed Policy at Growth Inflection-Economy Overheats(08/2021) | C87: 2461 | D87: The US economy recovers sharply following a successful vaccine rollout, leading to elevated risk asset valuations and unexpectedly high inflation. Faced with apparent economic overheating, the Fed hastens its tapering of asset purchases and pulls rate hike expectations forward to early 2022. | E87: 15yr Mtg Tsy Basis USD_mtg15_tsy - Mortgage Basis: 20.00bps, | F87: 15yr Mtg Tsy Basis | G87: =+VLOOKUP(F87,[1]Explore!$B:$I,8,0) -> Mortgage Basis | H87: USD_mtg15_tsy | I87: =+VLOOKUP(H87,[1]Explore!$A:$I,9,0) -> Mortgage Basis | J87: =IF(AND(ISNA(G87),ISNA(I87)),"BOTH #N/A","OK") -> OK | K87: =IFERROR(I87, IFERROR(G87, L87)) -> Mortgage Basis | L87: Mortgage Basis | M87: =_xlfn.IFNA(VLOOKUP(K87,'Mapping DEF'!A:C,2,0),"") -> Alternative | N87: =+_xlfn.IFNA(VLOOKUP(M87,'Mapping DEF'!B:C,2,FALSE),"") -> Other | O87: 20.00bps
A88: CB_OVER | B88: Fed Policy at Growth Inflection-Economy Overheats(08/2021) | C88: 2461 | D88: The US economy recovers sharply following a successful vaccine rollout, leading to elevated risk asset valuations and unexpectedly high inflation. Faced with apparent economic overheating, the Fed hastens its tapering of asset purchases and pulls rate hike expectations forward to early 2022. | E88: Brent Crude ICE 1 USD_COMD_CO_1 - Price Level: 7.00pct, | F88: Brent Crude ICE 1 | G88: =+VLOOKUP(F88,[1]Explore!$B:$I,8,0) -> Alternative - Commodity | H88: USD_COMD_CO_1 | I88: =+VLOOKUP(H88,[1]Explore!$A:$I,9,0) -> Alternative - Commodity | J88: =IF(AND(ISNA(G88),ISNA(I88)),"BOTH #N/A","OK") -> OK | K88: =IFERROR(I88, IFERROR(G88, L88)) -> Alternative - Commodity | L88: Price Level | M88: =_xlfn.IFNA(VLOOKUP(K88,'Mapping DEF'!A:C,2,0),"") -> Alternative | N88: =+_xlfn.IFNA(VLOOKUP(M88,'Mapping DEF'!B:C,2,FALSE),"") -> Other | O88: 7.00pct
A89: CB_OVER | B89: Fed Policy at Growth Inflection-Economy Overheats(08/2021) | C89: 2461 | D89: The US economy recovers sharply following a successful vaccine rollout, leading to elevated risk asset valuations and unexpectedly high inflation. Faced with apparent economic overheating, the Fed hastens its tapering of asset purchases and pulls rate hike expectations forward to early 2022. | E89: Gold COMEX 1 USD_COMD_GC_1 - Price Level: 5.00pct, | F89: Gold COMEX 1 | G89: =+VLOOKUP(F89,[1]Explore!$B:$I,8,0) -> Alternative - Commodity | H89: USD_COMD_GC_1 | I89: =+VLOOKUP(H89,[1]Explore!$A:$I,9,0) -> Alternative - Commodity | J89: =IF(AND(ISNA(G89),ISNA(I89)),"BOTH #N/A","OK") -> OK | K89: =IFERROR(I89, IFERROR(G89, L89)) -> Alternative - Commodity | L89: Price Level | M89: =_xlfn.IFNA(VLOOKUP(K89,'Mapping DEF'!A:C,2,0),"") -> Alternative | N89: =+_xlfn.IFNA(VLOOKUP(M89,'Mapping DEF'!B:C,2,FALSE),"") -> Other | O89: 5.00pct
A90: CB_OVER | B90: Fed Policy at Growth Inflection-Economy Overheats(08/2021) | C90: 2461 | D90: The US economy recovers sharply following a successful vaccine rollout, leading to elevated risk asset valuations and unexpectedly high inflation. Faced with apparent economic overheating, the Fed hastens its tapering of asset purchases and pulls rate hike expectations forward to early 2022. | E90: US Cash Bonds IG USD_LEH_CREDIT3 - Spread Yield: 20.00bps, | F90: US Cash Bonds IG | G90: =+VLOOKUP(F90,[1]Explore!$B:$I,8,0) -> Corporate IG USD - Other | H90: USD_LEH_CREDIT3 | I90: =+VLOOKUP(H90,[1]Explore!$A:$I,9,0) -> Corporate IG USD - Other | J90: =IF(AND(ISNA(G90),ISNA(I90)),"BOTH #N/A","OK") -> OK | K90: =IFERROR(I90, IFERROR(G90, L90)) -> Corporate IG USD - Other | L90: Corporate IG USD - Other | M90: =_xlfn.IFNA(VLOOKUP(K90,'Mapping DEF'!A:C,2,0),"") -> Spread | N90: =+_xlfn.IFNA(VLOOKUP(M90,'Mapping DEF'!B:C,2,FALSE),"") -> Spread | O90: 20.00bps
A91: CB_OVER | B91: Fed Policy at Growth Inflection-Economy Overheats(08/2021) | C91: 2461 | D91: The US economy recovers sharply following a successful vaccine rollout, leading to elevated risk asset valuations and unexpectedly high inflation. Faced with apparent economic overheating, the Fed hastens its tapering of asset purchases and pulls rate hike expectations forward to early 2022. | E91: DXY DXY - Index Level: 3.00pct, | F91: DXY | G91: =+VLOOKUP(F91,[1]Explore!$B:$I,8,0) -> #N/A | H91: DXY | I91: =+VLOOKUP(H91,[1]Explore!$A:$I,9,0) -> #N/A | J91: =IF(AND(ISNA(G91),ISNA(I91)),"BOTH #N/A","OK") -> BOTH #N/A | K91: =IFERROR(I91, IFERROR(G91, L91)) -> Dollar Index | L91: Dollar Index | M91: =_xlfn.IFNA(VLOOKUP(K91,'Mapping DEF'!A:C,2,0),"") -> Index Level | N91: =+_xlfn.IFNA(VLOOKUP(M91,'Mapping DEF'!B:C,2,FALSE),"") -> Other | O91: 3.00pct
A92: CB_OVER | B92: Fed Policy at Growth Inflection-Economy Overheats(08/2021) | C92: 2461 | D92: The US economy recovers sharply following a successful vaccine rollout, leading to elevated risk asset valuations and unexpectedly high inflation. Faced with apparent economic overheating, the Fed hastens its tapering of asset purchases and pulls rate hike expectations forward to early 2022. | E92: S&P 500 SPX - Index Level: -8.00pct, | F92: S&P 500 | G92: =+VLOOKUP(F92,[1]Explore!$B:$I,8,0) -> Equity Implied Volatility | H92: SPX | I92: =+VLOOKUP(H92,[1]Explore!$A:$I,9,0) -> Equity Implied Volatility | J92: =IF(AND(ISNA(G92),ISNA(I92)),"BOTH #N/A","OK") -> OK | K92: =IFERROR(I92, IFERROR(G92, L92)) -> Equity Implied Volatility | L92: Index Level | M92: =_xlfn.IFNA(VLOOKUP(K92,'Mapping DEF'!A:C,2,0),"") -> Equity Derivatives | N92: =+_xlfn.IFNA(VLOOKUP(M92,'Mapping DEF'!B:C,2,FALSE),"") -> Equity | O92: -8.00pct
A93: CB_OVER | B93: Fed Policy at Growth Inflection-Economy Overheats(08/2021) | C93: 2461 | D93: The US economy recovers sharply following a successful vaccine rollout, leading to elevated risk asset valuations and unexpectedly high inflation. Faced with apparent economic overheating, the Fed hastens its tapering of asset purchases and pulls rate hike expectations forward to early 2022. | E93: Time ALL_TIME - Time: 30.00days, | F93: Time | G93: =+VLOOKUP(F93,[1]Explore!$B:$I,8,0) -> #N/A | H93: ALL_TIME | I93: =+VLOOKUP(H93,[1]Explore!$A:$I,9,0) -> #N/A | J93: =IF(AND(ISNA(G93),ISNA(I93)),"BOTH #N/A","OK") -> BOTH #N/A | K93: =IFERROR(I93, IFERROR(G93, L93)) -> Time | L93: Time | M93: =_xlfn.IFNA(VLOOKUP(K93,'Mapping DEF'!A:C,2,0),"") -> Time | N93: =+_xlfn.IFNA(VLOOKUP(M93,'Mapping DEF'!B:C,2,FALSE),"") -> Other | O93: 30.00days
...

Sheet Sheet11
A1: MAPPING_DEF | B1: Mapping 1 Livello | C1: Mapping 2 Livello | F1: MAPPING_DEF_1 LIV | K1: Mapping 3 livello | L1: Mapping 2 livello | M1: Mapping 1 Livello
A2: Equity Implied Volatility | B2: Equity Derivatives | C2: Equity | F2: Equity Derivatives | K2: Govt USD | L2: =+VLOOKUP(K2,A:B,2,FALSE) -> Curve (Local) | M2: =+VLOOKUP(L2,B:C,2,FALSE) -> Term Structure
A3: Govt USD | B3: Curve (Local) | C3: Term Structure | F3: Curve (Local) | K3: Equity Implied Volatility | L3: =+VLOOKUP(K3,A:B,2,FALSE) -> Equity Derivatives | M3: =+VLOOKUP(L3,B:C,2,FALSE) -> Equity
A4: Emerging Currency | B4: FX | C4: FX | F4: Alternative | K4: Alternative - Commodity | L4: =+VLOOKUP(K4,A:B,2,FALSE) -> Alternative | M4: Other
A5: Industrials | B5: Industry Allocation | C5: Equity | F5: Spread | K5: Emerging Currency | L5: =+VLOOKUP(K5,A:B,2,FALSE) -> FX | M5: =+VLOOKUP(L5,B:C,2,FALSE) -> FX
A6: Alternative - Commodity | B6: Alternative | C6: Alternative | F6: FX | K6: Industrials | L6: =+VLOOKUP(K6,A:B,2,FALSE) -> Industry Allocation | M6: =+VLOOKUP(L6,B:C,2,FALSE) -> Equity
A7: Information Technology | B7: Industry Allocation | C7: Equity | F7: Industry Allocation | K7: Information Technology | L7: =+VLOOKUP(K7,A:B,2,FALSE) -> Industry Allocation | M7: =+VLOOKUP(L7,B:C,2,FALSE) -> Equity
A8: Corporate HY USD - Industry | B8: Spread | C8: Spread | F8: Industry Return | K8: Corporate HY USD - Industry | L8: =+VLOOKUP(K8,A:B,2,FALSE) -> Spread | M8: =+VLOOKUP(L8,B:C,2,FALSE) -> Spread
A9: Industry Return | B9: =A9 -> Industry Return | C9: Equity | F9: Inflation | K9: Industry Return | L9: =+VLOOKUP(K9,A:B,2,FALSE) -> Industry Return | M9: =+VLOOKUP(L9,B:C,2,FALSE) -> Equity
A10: USD Inflation | B10: Inflation | C10: Inflation | F10: Other | K10: USD Inflation | L10: =+VLOOKUP(K10,A:B,2,FALSE) -> Inflation | M10: Other
A11: Govt EUR (Ger) | B11: Curve (Local) | C11: Term Structure | F11: Time | K11: Govt EUR (Ger) | L11: =+VLOOKUP(K11,A:B,2,FALSE) -> Curve (Local) | M11: =+VLOOKUP(L11,B:C,2,FALSE) -> Term Structure
A12: Govt Developed Other (AU, GB, JP, ...) | B12: Curve (Local) | C12: Term Structure | F12: Index Level | K12: Govt Developed Other (AU, GB, JP, ...) | L12: =+VLOOKUP(K12,A:B,2,FALSE) -> Curve (Local) | M12: =+VLOOKUP(L12,B:C,2,FALSE) -> Term Structure
A13: JPY | B13: FX | C13: FX | F13: Country Allocation | K13: JPY | L13: =+VLOOKUP(K13,A:B,2,FALSE) -> FX | M13: =+VLOOKUP(L13,B:C,2,FALSE) -> FX
A14: Other - Index | B14: Other | C14: Other | F14: Spread Govt | K14: Other - Index | L14: =+VLOOKUP(K14,A:B,2,FALSE) -> Other | M14: =+VLOOKUP(L14,B:C,2,FALSE) -> Other
A15: EUR | B15: FX | C15: FX | F15: Style | K15: EUR | L15: =+VLOOKUP(K15,A:B,2,FALSE) -> FX | M15: =+VLOOKUP(L15,B:C,2,FALSE) -> FX
A16: GBP | B16: FX | C16: FX | F16: Spread Yield | K16: GBP | L16: =+VLOOKUP(K16,A:B,2,FALSE) -> FX | M16: =+VLOOKUP(L16,B:C,2,FALSE) -> FX
A17: Time | B17: Time | C17: Time | F17: Commodity | K17: Corporate IG Other - Other | L17: =+VLOOKUP(K17,A:B,2,FALSE) -> Spread | M17: =+VLOOKUP(L17,B:C,2,FALSE) -> Spread
A18: Corporate IG Other - Other | B18: Spread | C18: Spread | F18: Style Return | K18: Time | L18: =+VLOOKUP(K18,A:B,2,FALSE) -> Time | M18: Other
A19: Index Level | B19: =A19 -> Index Level | C19: Dollar Index | F19: Yield | K19: Spread - Municipals | L19: =+VLOOKUP(K19,A:B,2,FALSE) -> Spread | M19: =+VLOOKUP(L19,B:C,2,FALSE) -> Spread
A20: Spread - Municipals | B20: Spread | C20: Spread | F20: Price Level | K20: Index Level | L20: =+VLOOKUP(K20,A:B,2,FALSE) -> Index Level | M20: Other
A21: Health Care | B21: Industry Allocation | C21: Equity | F21: Rates Implied Volatility | K21: Health Care | L21: =+VLOOKUP(K21,A:B,2,FALSE) -> Industry Allocation | M21: =+VLOOKUP(L21,B:C,2,FALSE) -> Equity
A22: Corporate HY USD - Other | B22: Spread | C22: Spread | K22: Utilities | L22: =+VLOOKUP(K22,A:B,2,FALSE) -> Industry Allocation | M22: =+VLOOKUP(L22,B:C,2,FALSE) -> Equity
A23: Utilities | B23: Industry Allocation | C23: Equity | K23: Corporate HY USD - Other | L23: =+VLOOKUP(K23,A:B,2,FALSE) -> Spread | M23: =+VLOOKUP(L23,B:C,2,FALSE) -> Spread
A24: Consumer Discretionary | B24: Industry Allocation | C24: Equity | K24: Consumer Discretionary | L24: =+VLOOKUP(K24,A:B,2,FALSE) -> Industry Allocation | M24: =+VLOOKUP(L24,B:C,2,FALSE) -> Equity
A25: Mortgage Basis | B25: Alternative | C25: Alternative | K25: Mortgage Basis | L25: =+VLOOKUP(K25,A:B,2,FALSE) -> Alternative | M25: Other
A26: Corporate IG USD - Other | B26: Spread | C26: Spread | K26: Corporate IG USD - Other | L26: =+VLOOKUP(K26,A:B,2,FALSE) -> Spread | M26: =+VLOOKUP(L26,B:C,2,FALSE) -> Spread
A27: ABS - Swap Spread | B27: Alternative | C27: Alternative | K27: ABS - Swap Spread | L27: =+VLOOKUP(K27,A:B,2,FALSE) -> Alternative | M27: Other
A28: Mortgage | B28: Alternative | C28: Alternative | K28: Mortgage | L28: =+VLOOKUP(K28,A:B,2,FALSE) -> Alternative | M28: Other
A29: Materials | B29: Industry Allocation | C29: Equity | K29: Materials | L29: =+VLOOKUP(K29,A:B,2,FALSE) -> Industry Allocation | M29: =+VLOOKUP(L29,B:C,2,FALSE) -> Equity
A30: Spread Emerging Markets - Country | B30: Spread | C30: Spread | K30: Spread Emerging Markets - Country | L30: =+VLOOKUP(K30,A:B,2,FALSE) -> Spread | M30: =+VLOOKUP(L30,B:C,2,FALSE) -> Spread
A31: Govt Emerging Markets | B31: Curve (Local) | C31: Term Structure | K31: Spread Govt ITA | L31: =+VLOOKUP(K31,A:B,2,FALSE) -> Spread Govt | M31: =+VLOOKUP(L31,B:C,2,FALSE) -> Term Structure
A32: Consumer Staples | B32: Industry Allocation | C32: Equity | K32: Govt Emerging Markets | L32: =+VLOOKUP(K32,A:B,2,FALSE) -> Curve (Local) | M32: =+VLOOKUP(L32,B:C,2,FALSE) -> Term Structure
A33: Spread Govt ITA | B33: Spread Govt | C33: Term Structure | K33: Emerging Markets | L33: =+VLOOKUP(K33,A:B,2,FALSE) -> Country Allocation | M33: =+VLOOKUP(L33,B:C,2,FALSE) -> Equity
A34: Emerging Markets | B34: Country Allocation | C34: Equity | K34: Other - Spread Yield | L34: =+VLOOKUP(K34,A:B,2,FALSE) -> Other | M34: =+VLOOKUP(L34,B:C,2,FALSE) -> Other
A35: Other - Spread Yield | B35: Other | C35: Other | K35: Consumer Staples | L35: =+VLOOKUP(K35,A:B,2,FALSE) -> Industry Allocation | M35: =+VLOOKUP(L35,B:C,2,FALSE) -> Equity
A36: Real Estate | B36: Industry Allocation | C36: Equity | K36: Corporate HY Other - Maturity | L36: =+VLOOKUP(K36,A:B,2,FALSE) -> Spread | M36: =+VLOOKUP(L36,B:C,2,FALSE) -> Spread
A37: Developed Currency | B37: FX | C37: FX | K37: Corporate IG USD - Industry | L37: =+VLOOKUP(K37,A:B,2,FALSE) -> Spread | M37: =+VLOOKUP(L37,B:C,2,FALSE) -> Spread
A38: Corporate HY Other - Maturity | B38: Spread | C38: Spread | K38: Local Styles | L38: =+VLOOKUP(K38,A:B,2,FALSE) -> Style | M38: =+VLOOKUP(L38,B:C,2,FALSE) -> Equity
A39: Local Styles | B39: Style | C39: Equity | K39: Corporate HY EUR - Industry | L39: =+VLOOKUP(K39,A:B,2,FALSE) -> Spread | M39: =+VLOOKUP(L39,B:C,2,FALSE) -> Spread
A40: Corporate HY EUR - Industry | B40: Spread | C40: Spread | K40: Real Estate | L40: =+VLOOKUP(K40,A:B,2,FALSE) -> Industry Allocation | M40: =+VLOOKUP(L40,B:C,2,FALSE) -> Equity
...

Sheet Pivot
A1: Stress_Scenarios | B1: Mapping 1 Livello | C1: Mapping 2 livello | D1: Mapping 3 livello | E1: Shock_Value | F1: Unnamed: 6
A2: 1995_MCADJ | B2: Equity | C2: Equity Derivatives | D2: Equity Implied Volatility | E2: 17.00pct | F2: SP500 Consum Discr S5COND - Index Level: 17.00pct,
A3: 1995_MCADJ | B3: Equity | C3: Equity Derivatives | D3: Equity Implied Volatility | E3: 24.00pct | F3: SP500 Consum Stapl S5CONS - Index Level: 24.00pct,
A4: 1995_MCADJ | B4: Equity | C4: Equity Derivatives | D4: Equity Implied Volatility | E4: 26.00pct | F4: S&P 500 Industrials S5INDU - Index Level: 26.00pct,
A5: 1995_MCADJ | B5: Equity | C5: Equity Derivatives | D5: Equity Implied Volatility | E5: 29.00pct | F5: S&P 500 Energy S5ENRS - Index Level: 29.00pct,
A6: 1995_MCADJ | B6: Equity | C6: Equity Derivatives | D6: Equity Implied Volatility | E6: 29.00pct | F6: S&P 500 Technology S5INFT - Index Level: 29.00pct,
A7: 1995_MCADJ | B7: Equity | C7: Equity Derivatives | D7: Equity Implied Volatility | E7: 32.00pct | F7: S&P Mid Cap MID - Index Level: 32.00pctc,
A8: 1995_MCADJ | B8: Equity | C8: Equity Derivatives | D8: Equity Implied Volatility | E8: 33.00pct | F8: S&P 500 Health Care S5HLTH - Index Level: 33.00pct,
A9: 1995_MCADJ | B9: Equity | C9: Equity Derivatives | D9: Equity Implied Volatility | E9: 37.00pct | F9: S&P 500 Utilities S5UTIL - Index Level: 37.00pct,
A10: 1995_MCADJ | B10: Equity | C10: Equity Derivatives | D10: Equity Implied Volatility | E10: 38.00pct | F10: S&P 500 Financials S5FINL - Index Level: 38.00pct,
A11: 1995_MCADJ | B11: Equity | C11: Equity Derivatives | D11: Equity Implied Volatility | E11: 47.00pct | F11: S&P Small Cap SML - Index Level: 47.00pct
A12: 1995_MCADJ | B12: Equity | C12: Equity Derivatives | D12: Equity Implied Volatility | E12: 49.00pct | F12: SP500 Communications S5TELS - Index Level: 49.00pct,
... A81: BTAX_COMP | B81: Term Structure | C81: Curve (Local) | D81: Govt USD | E81: 20.00bps | F81: Tsy 10Y USD_10yr - Yield: 20.00bps,
A82: C07_ABS | D82: - | E82: (blank) | F82: -
A83: C08_REL | D83: - | E83: (blank) | F83: -
A84: CB_OVER | B84: Equity | C84: Equity Derivatives | D84: Equity Implied Volatility | E84: -8.00pct | F84: S&P 500 SPX - Index Level: -8.00pct,
A85: CB_OVER | B85: Other | C85: Alternative | D85: Alternative - Commodity | E85: 5.00pct | F85: Gold COMEX 1 USD_COMD_GC_1 - Price Level: 5.00pct,
A86: CB_OVER | B86: Other | C86: Alternative | D86: Alternative - Commodity | E86: 7.00pct | F86: Brent Crude ICE 1 USD_COMD_CO_1 - Price Level: 7.00pct,
A87: CB_OVER | B87: Other | C87: Alternative | D87: Mortgage Basis | E87: 20.00bps | F87: 15yr Mtg Tsy Basis USD_mtg15_tsy - Mortgage Basis: 20.00bps,
A88: CB_OVER | B88: Other | C88: Index Level | D88: Dollar Index | E88: 3.00pct | F88: DXY DXY - Index Level: 3.00pct,
A89: CB_OVER | B89: Other | C89: Inflation | D89: USD Inflation | E89: -50.00bps | F89: USD INF 10Y USD_INF_10yr - Yield: -50.00bps,
A90: CB_OVER | B90: Other | C90: Other | D90: Other - Index | E90: 10.00pct | F90: S&P 500 Consumer Staples Index - S&P 500 [SPCS-SPX] - Index Level: 10.00pct
A91: CB_OVER | B91: Other | C91: Time | D91: Time | E91: 30.00days | F91: Time ALL_TIME - Time: 30.00days,
A92: CB_OVER | B92: Spread | C92: Spread | D92: Corporate HY USD - Other | E92: 50.00bps | F92: US HY Market USD_HY_MARKET - Spread Yield: 50.00bps,
A93: CB_OVER | B93: Spread | C93: Spread | D93: Corporate IG USD - Other | E93: 20.00bps | F93: US Cash Bonds IG USD_LEH_CREDIT3 - Spread Yield: 20.00bps,
A94: CB_OVER | B94: Term Structure | C94: Curve (Local) | D94: Govt USD | E94: 20.00bps | F94: Tsy 2Y USD_2yr - Yield: 20.00bps,
A95: CB_OVER | B95: Term Structure | C95: Curve (Local) | D95: Govt USD | E95: 45.00bps | F95: Tsy 10Y USD_10yr - Yield: 45.00bps,
... A134: CEM_ASIA | B134: Term Structure | C134: Curve (Local) | D134: Govt USD | E134: -20.00bps | F134: Tsy 10Y USD_10yr - Yield -20.00 bps,
A135: CEM_LATAM | D135: Other - Spread Yield | E135: 200.00bps | F135: Middle East and Africa USD_EM_CORP_MIDAF - Spread Yield 200.00 bps
A136: CEM_LATAM | B136: Equity | C136: Country Allocation | D136: Emerging Markets | E136: -10.00pct | F136: Saudi Arabia FMI_WRLD_SAU - Country Return -10.00 pct,
A137: CEM_LATAM | B137: Equity | C137: Equity Derivatives | D137: Equity Implied Volatility | E137: -10.00pct | F137: MSCI EUROPE(EUR) MXEU - Index Level -10.00 pct,
A138: CEM_LATAM | B138: Equity | C138: Equity Derivatives | D138: Equity Implied Volatility | E138: 30.00pct | F138: VIX VIX - Index Level 30.00 pct,
A139: CEM_LATAM | B139: Equity | C139: Industry Allocation | D139: Consumer Discretionary | E139: -15.00pct | F139: Hotels Restaurants & Leisure FMI_EMEA_CDIHOTREST - Industry Return -15.00 pct,
A140: CEM_LATAM | B140: Equity | C140: Industry Allocation | D140: Consumer Staples | E140: 10.00pct | F140: Cons Staples x Alcohol & Tob FMI_LATC_CSTXALCTOB - Industry Return 10.00 pct,
A141: CEM_LATAM | B141: Equity | C141: Industry Allocation | D141: Financials | E141: -10.00pct | F141: Banks FMI_LATC_FINBANK - Industry Return -10.00 pct,
A142: CEM_LATAM | B142: FX | C142: FX | D142: Emerging Currency | E142: -10.00pct | F142: RUB/USD RUB_FX_USD - FX -10.00 pct,
A143: CEM_LATAM | B143: FX | C143: FX | D143: Emerging Currency | E143: -20.00pct | F143: BRL/USD BRL_FX_USD - FX -20.00 pct,
A144: CEM_LATAM | B144: FX | C144: FX | D144: Emerging Currency | E144: -5.00pct | F144: CZK/USD CZK_FX_USD - FX -5.00 pct,
A145: CEM_LATAM | B145: Other | C145: Alternative | D145: Alternative - Commodity | E145: -30.00pct | F145: Brent Crude ICE 1 USD_COMD_CO_1 - Price Level -30.00 pct,
A146: CEM_LATAM | B146: Other | C146: Index Level | D146: Dollar Index | E146: 3.00pct | F146: DXY DXY - Index Level 3.00 pct,
...

Sheet Mapping DEF
A1: Mapping 3 livello | B1: Mapping 2 livello | C1: Mapping 1 Livello
A2: Govt USD | B2: Curve (Local) | C2: Term Structure
A3: Equity Implied Volatility | B3: Equity Derivatives | C3: Equity
A4: Alternative - Commodity | B4: Alternative | C4: Other
A5: Emerging Currency | B5: FX | C5: FX
A6: Industrials | B6: Industry Allocation | C6: Equity
A7: Information Technology | B7: Industry Allocation | C7: Equity
A8: Corporate HY USD - Industry | B8: Spread | C8: Spread
A9: USD Inflation | B9: Inflation | C9: Other
A10: Govt EUR (Ger) | B10: Curve (Local) | C10: Term Structure
A11: Govt Developed Other (AU, GB, JP, ...) | B11: Curve (Local) | C11: Term Structure
A12: JPY | B12: FX | C12: FX
... A71: Corporate HY USD - Maturity | B71: Spread | C71: Spread
